<sdf version='1.7'>
  <model name='ur5e'>
    <joint name='world_joint' type='fixed'>
      <pose relative_to='__model__'>0 0 0 0 -0 0</pose>
      <parent>world</parent>
      <child>base_link</child>
    </joint>
    <link name='base_link'>
      <pose relative_to='world_joint'>0 0 0 0 -0 0</pose>
      <inertial>
        <pose>0 0 0 0 -0 0</pose>
        <mass>4</mass>
        <inertia>
          <ixx>0.00443333</ixx>
          <ixy>0</ixy>
          <ixz>0</ixz>
          <iyy>0.00443333</iyy>
          <iyz>0</iyz>
          <izz>0.0072</izz>
        </inertia>
      </inertial>
      <visual name='base_link_visual'>
        <pose>0 0 0 0 -0 0</pose>
        <geometry>
          <mesh>
            <scale>1 1 1</scale>
            <uri>model://cable_routing/models/ur5e_description/meshes/visual/base.dae</uri>
          </mesh>
        </geometry>
      </visual>
    </link>
    <joint name='shoulder_pan_joint' type='revolute'>
      <pose relative_to='base_link'>0 0 0.163 0 -0 0</pose>
      <parent>base_link</parent>
      <child>shoulder_link</child>
      <axis>
        <xyz>0 0 1</xyz>
        <limit>
          <lower>-6.28319</lower>
          <upper>6.28319</upper>
          <effort>150</effort>
          <velocity>3.14</velocity>
        </limit>
        <dynamics>
          <damping>0</damping>
          <friction>0</friction>
          <spring_reference>0</spring_reference>
          <spring_stiffness>0</spring_stiffness>
        </dynamics>
      </axis>
    </joint>
    <link name='shoulder_link'>
      <pose relative_to='shoulder_pan_joint'>0 0 0 0 -0 0</pose>
      <inertial>
        <pose>0 0 0 0 -0 0</pose>
        <mass>3.7</mass>
        <inertia>
          <ixx>0.0102675</ixx>
          <ixy>0</ixy>
          <ixz>0</ixz>
          <iyy>0.0102675</iyy>
          <iyz>0</iyz>
          <izz>0.00666</izz>
        </inertia>
      </inertial>
      <visual name='shoulder_link_visual'>
        <pose>0 0 0 0 -0 0</pose>
        <geometry>
          <mesh>
            <scale>1 1 1</scale>
            <uri>model://cable_routing/models/ur5e_description/meshes/visual/shoulder.dae</uri>
          </mesh>
        </geometry>
      </visual>
      
    </link>
    <joint name='shoulder_lift_joint' type='revolute'>
      <pose relative_to='shoulder_link'>0 0.138 0 0 1.5708 0</pose>
      <parent>shoulder_link</parent>
      <child>upper_arm_link</child>
      <axis>
        <xyz>0 1 0</xyz>
        <limit>
          <lower>-6.28319</lower>
          <upper>6.28319</upper>
          <effort>150</effort>
          <velocity>3.14</velocity>
        </limit>
        <dynamics>
          <damping>0</damping>
          <friction>0</friction>
          <spring_reference>0</spring_reference>
          <spring_stiffness>0</spring_stiffness>
        </dynamics>
      </axis>
    </joint>
    <link name='upper_arm_link'>
      <pose relative_to='shoulder_lift_joint'>0 0 0 0 -0 0</pose>
      <inertial>
        <pose>0 0 0.2125 0 -0 0</pose>
        <mass>8.393</mass>
        <inertia>
          <ixx>0.133886</ixx>
          <ixy>0</ixy>
          <ixz>0</ixz>
          <iyy>0.133886</iyy>
          <iyz>0</iyz>
          <izz>0.0151074</izz>
        </inertia>
      </inertial>
      <visual name='upper_arm_link_visual'>
        <pose>0 0 0 0 -0 0</pose>
        <geometry>
          <mesh>
            <scale>1 1 1</scale>
            <uri>model://cable_routing/models/ur5e_description/meshes/visual/upperarm.dae</uri>
          </mesh>
        </geometry>
      </visual>
      
    </link>
    <joint name='elbow_joint' type='revolute'>
      <pose relative_to='upper_arm_link'>0 -0.131 0.425 0 -0 0</pose>
      <parent>upper_arm_link</parent>
      <child>forearm_link</child>
      <axis>
        <xyz>0 1 0</xyz>
        <limit>
          <lower>-3.14159</lower>
          <upper>3.14159</upper>
          <effort>150</effort>
          <velocity>3.14</velocity>
        </limit>
        <dynamics>
          <damping>0</damping>
          <friction>0</friction>
          <spring_reference>0</spring_reference>
          <spring_stiffness>0</spring_stiffness>
        </dynamics>
      </axis>
    </joint>
    <link name='forearm_link'>
      <pose relative_to='elbow_joint'>0 0 0 0 -0 0</pose>
      <inertial>
        <pose>0 0 0.196 0 -0 0</pose>
        <mass>2.275</mass>
        <inertia>
          <ixx>0.0311796</ixx>
          <ixy>0</ixy>
          <ixz>0</ixz>
          <iyy>0.0311796</iyy>
          <iyz>0</iyz>
          <izz>0.004095</izz>
        </inertia>
      </inertial>
      <visual name='forearm_link_visual'>
        <pose>0 0 0 0 -0 0</pose>
        <geometry>
          <mesh>
            <scale>1 1 1</scale>
            <uri>model://cable_routing/models/ur5e_description/meshes/visual/forearm.dae</uri>
          </mesh>
        </geometry>
      </visual>
      
    </link>
    <joint name='wrist_1_joint' type='revolute'>
      <pose relative_to='forearm_link'>0 0 0.392 0 1.5708 0</pose>
      <parent>forearm_link</parent>
      <child>wrist_1_link</child>
      <axis>
        <xyz>0 1 0</xyz>
        <limit>
          <lower>-6.28319</lower>
          <upper>6.28319</upper>
          <effort>28</effort>
          <velocity>6.28</velocity>
        </limit>
        <dynamics>
          <damping>0</damping>
          <friction>0</friction>
          <spring_reference>0</spring_reference>
          <spring_stiffness>0</spring_stiffness>
        </dynamics>
      </axis>
    </joint>
    <link name='wrist_1_link'>
      <pose relative_to='wrist_1_joint'>0 0 0 0 -0 0</pose>
      <inertial>
        <pose>0 0.127 0 0 -0 0</pose>
        <mass>1.219</mass>
        <inertia>
          <ixx>0.0025599</ixx>
          <ixy>0</ixy>
          <ixz>0</ixz>
          <iyy>0.0025599</iyy>
          <iyz>0</iyz>
          <izz>0.0021942</izz>
        </inertia>
      </inertial>
      <visual name='wrist_1_link_visual'>
        <pose>0 0 0 0 -0 0</pose>
        <geometry>
          <mesh>
            <scale>1 1 1</scale>
            <uri>model://cable_routing/models/ur5e_description/meshes/visual/wrist1.dae</uri>
          </mesh>
        </geometry>
      </visual>
      
    </link>
    <joint name='wrist_2_joint' type='revolute'>
      <pose relative_to='wrist_1_link'>0 0.127 0 0 -0 0</pose>
      <parent>wrist_1_link</parent>
      <child>wrist_2_link</child>
      <axis>
        <xyz>0 0 1</xyz>
        <limit>
          <lower>-6.28319</lower>
          <upper>6.28319</upper>
          <effort>28</effort>
          <velocity>6.28</velocity>
        </limit>
        <dynamics>
          <damping>0</damping>
          <friction>0</friction>
          <spring_reference>0</spring_reference>
          <spring_stiffness>0</spring_stiffness>
        </dynamics>
      </axis>
    </joint>
    <link name='wrist_2_link'>
      <pose relative_to='wrist_2_joint'>0 0 0 0 -0 0</pose>
      <inertial>
        <pose>0 0 0.1 0 -0 0</pose>
        <mass>1.219</mass>
        <inertia>
          <ixx>0.0025599</ixx>
          <ixy>0</ixy>
          <ixz>0</ixz>
          <iyy>0.0025599</iyy>
          <iyz>0</iyz>
          <izz>0.0021942</izz>
        </inertia>
      </inertial>
      <visual name='wrist_2_link_visual'>
        <pose>0 0 0 0 -0 0</pose>
        <geometry>
          <mesh>
            <scale>1 1 1</scale>
            <uri>model://cable_routing/models/ur5e_description/meshes/visual/wrist2.dae</uri>
          </mesh>
        </geometry>
      </visual>
      
    </link>
    <joint name='wrist_3_joint' type='revolute'>
      <pose relative_to='wrist_2_link'>0 0 0.1 0 -0 0</pose>
      <parent>wrist_2_link</parent>
      <child>wrist_3_link</child>
      <axis>
        <xyz>0 1 0</xyz>
        <limit>
          <lower>-6.28319</lower>
          <upper>6.28319</upper>
          <effort>28</effort>
          <velocity>6.28</velocity>
        </limit>
        <dynamics>
          <damping>0</damping>
          <friction>0</friction>
          <spring_reference>0</spring_reference>
          <spring_stiffness>0</spring_stiffness>
        </dynamics>
      </axis>
    </joint>
    <link name='wrist_3_link'>
      <pose relative_to='wrist_3_joint'>0 0 0 0 -0 0</pose>
      <inertial>
        <pose>0 0.0771 0 1.5708 -0 0</pose>
        <mass>0.1879</mass>
        <inertia>
          <ixx>9.89041e-05</ixx>
          <ixy>0</ixy>
          <ixz>0</ixz>
          <iyy>9.89041e-05</iyy>
          <iyz>0</iyz>
          <izz>0.000132117</izz>
        </inertia>
      </inertial>
      <visual name='wrist_3_link_visual'>
        <pose>0 0 0 0 -0 0</pose>
        <geometry>
          <mesh>
            <scale>1 1 1</scale>
            <uri>model://cable_routing/models/ur5e_description/meshes/visual/wrist3.dae</uri>
          </mesh>
        </geometry>
      </visual>
      
    </link>
  </model>
</sdf>
